<?xml version="1.0" encoding="UTF-8"?>
<sdf version='1.9'>
  <model name='x500withArms'>
    <pose>0 0 .24 0 0 0</pose>
    <self_collide>false</self_collide>
    <static>false</static>
    <link name="base_link">
      <inertial>
        <mass>2.0</mass>
        <inertia>
          <ixx>0.02166666666666667</ixx>
          <ixy>0</ixy>
          <ixz>0</ixz>
          <iyy>0.02166666666666667</iyy>
          <iyz>0</iyz>
          <izz>0.04000000000000001</izz>
        </inertia>
      </inertial>
      <gravity>true</gravity>
      <velocity_decay/>
      <visual name="base_link_visual">
        <pose>-0.45 -0.285 -0.42 1.57079632679 0 1.57079632679</pose>
        <geometry>
          <mesh>
            <scale>1 1 1</scale>
            <uri>model://x500withArms/meshes/Holybro-X500-V2-no-landinggear-arm-attachments.dae</uri>
          </mesh>
        </geometry>
      </visual>
      <collision name="base_link_collision_0">
        <pose>0 0 .007 0 0 0</pose>
        <geometry>
          <box>
            <size>0.6 0.6 0.1</size>
          </box>
        </geometry>
        <surface>
          <contact>
            <ode>
              <min_depth>0.001</min_depth>
              <max_vel>0</max_vel>
            </ode>
          </contact>
          <friction>
            <ode/>
          </friction>
        </surface>
      </collision>
      <sensor name="air_pressure_sensor" type="air_pressure">
        <always_on>1</always_on>
        <update_rate>50</update_rate>
        <air_pressure>
          <pressure>
            <noise type="gaussian">
              <mean>0</mean>
              <stddev>0.01</stddev>
            </noise>
          </pressure>
        </air_pressure>
      </sensor>
      <sensor name="imu_sensor" type="imu">
        <always_on>1</always_on>
        <update_rate>250</update_rate>
      </sensor>
    </link>
    <!-- Dummy Arm 0 -->
    <include>
      <name>dummy_arm0</name>
      <uri>model://dummy_arm</uri>
      <pose>0.1325 0.1325 -0.06 3.1415926 0 0</pose>
    </include>
    <joint name="dummy_arm0_base_joint" type="fixed">
      <parent>base_link</parent>
      <child>dummy_arm0::base_link</child>
      <pose>0.1325 0.1325 -0.06 3.1415926 0 0</pose>
    </joint>
    <!-- Dummy Arm 1 -->
    <include>
      <name>dummy_arm1</name>
      <uri>model://dummy_arm</uri>
      <pose>0.1325 -0.1325 -0.06 3.1415926 0 0</pose>
    </include>
    <joint name="dummy_arm1_base_joint" type="fixed">
      <parent>base_link</parent>
      <child>dummy_arm1::base_link</child>
      <pose>0.1325 -0.1325 -0.06 3.1415926 0 0</pose>
    </joint>
    <!-- Dummy Arm 2 -->
    <include>
      <name>dummy_arm2</name>
      <uri>model://dummy_arm</uri>
      <pose>-0.1325 -0.1325 -0.06 3.1415926 0 0</pose>
    </include>
    <joint name="dummy_arm2_base_joint" type="fixed">
      <parent>base_link</parent>
      <child>dummy_arm2::base_link</child>
      <pose>-0.1325 -0.1325 -0.06 3.1415926 0 0</pose>
    </joint>
    <!-- Dummy Arm 3 -->
    <include>
      <name>dummy_arm3</name>
      <uri>model://dummy_arm</uri>
      <pose>-0.1325 0.1325 -0.06 3.1415926 0 0</pose>
    </include>
    <joint name="dummy_arm3_base_joint" type="fixed">
      <parent>base_link</parent>
      <child>dummy_arm3::base_link</child>
      <pose>-0.1325 0.1325 -0.06 3.1415926 0 0</pose>
    </joint>
    <link name="rotor_0">
      <gravity>true</gravity>
      <self_collide>false</self_collide>
      <velocity_decay/>
      <pose>0.174 -0.174 0.06 0 0 0</pose>
      <inertial>
          <mass>0.016076923076923075</mass>
          <inertia>
            <ixx>3.8464910483993325e-07</ixx>
            <iyy>2.6115851691700804e-05</iyy>
            <izz>2.649858234714004e-05</izz>
          </inertia>
        </inertial>
      <visual name="rotor_0_visual">
        <pose>-0.022 -0.14638461538461536 -0.016 0 0 0</pose>
        <geometry>
          <mesh>
            <scale>0.8461538461538461 0.8461538461538461 0.8461538461538461</scale>
            <uri>model://x500/meshes/1345_prop_ccw.stl</uri>
          </mesh>
        </geometry>
        <material>
          <script>
            <name>Gazebo/DarkGrey</name>
            <uri>file://media/materials/scripts/gazebo.material</uri>
          </script>
        </material>
      </visual>
      <collision name="rotor_0_collision">
        <pose>0 0 0 0 0 0 </pose>
        <geometry>
          <box>
            <size>0.2792307692307692 0.016923076923076923 0.0008461538461538462</size>
          </box>
        </geometry>
        <surface>
          <contact>
            <ode>
              <min_depth>0.001</min_depth>
              <max_vel>0</max_vel>
            </ode>
          </contact>
          <friction>
            <ode/>
          </friction>
        </surface>
      </collision>
    </link>
    <joint name="rotor_0_joint" type="revolute">
      <parent>base_link</parent>
      <child>rotor_0</child>
      <axis>
        <xyz>0 0 1</xyz>
        <limit>
          <lower>-1e+16</lower>
          <upper>1e+16</upper>
        </limit>
        <dynamics>
          <spring_reference>0</spring_reference>
          <spring_stiffness>0</spring_stiffness>
        </dynamics>
      </axis>
    </joint>
    <link name="rotor_1">
      <gravity>true</gravity>
      <self_collide>false</self_collide>
      <velocity_decay/>
      <pose>-0.174 0.174 0.06 0 0 0</pose>
      <inertial>
          <mass>0.016076923076923075</mass>
          <inertia>
            <ixx>3.8464910483993325e-07</ixx>
            <iyy>2.6115851691700804e-05</iyy>
            <izz>2.649858234714004e-05</izz>
          </inertia>
        </inertial>
      <visual name="rotor_1_visual">
        <pose>-0.022 -0.14638461538461536 -0.016 0 0 0</pose>
        <geometry>
          <mesh>
            <scale>0.8461538461538461 0.8461538461538461 0.8461538461538461</scale>
            <uri>model://x500/meshes/1345_prop_ccw.stl</uri>
          </mesh>
        </geometry>
        <material>
          <script>
            <name>Gazebo/DarkGrey</name>
            <uri>file://media/materials/scripts/gazebo.material</uri>
          </script>
        </material>
      </visual>
      <collision name="rotor_1_collision">
        <pose>0 0 0 0 0 0 </pose>
        <geometry>
          <box>
            <size>0.2792307692307692 0.016923076923076923 0.0008461538461538462</size>
          </box>
        </geometry>
        <surface>
          <contact>
            <ode>
              <min_depth>0.001</min_depth>
              <max_vel>0</max_vel>
            </ode>
          </contact>
          <friction>
            <ode/>
          </friction>
        </surface>
      </collision>
    </link>
    <joint name="rotor_1_joint" type="revolute">
      <parent>base_link</parent>
      <child>rotor_1</child>
      <axis>
        <xyz>0 0 1</xyz>
        <limit>
          <lower>-1e+16</lower>
          <upper>1e+16</upper>
        </limit>
        <dynamics>
          <spring_reference>0</spring_reference>
          <spring_stiffness>0</spring_stiffness>
        </dynamics>
      </axis>
    </joint>
    <link name="rotor_2">
      <gravity>true</gravity>
      <self_collide>false</self_collide>
      <velocity_decay/>
      <pose>0.174 0.174 0.06 0 0 0</pose>
      <inertial>
          <mass>0.016076923076923075</mass>
          <inertia>
            <ixx>3.8464910483993325e-07</ixx>
            <iyy>2.6115851691700804e-05</iyy>
            <izz>2.649858234714004e-05</izz>
          </inertia>
        </inertial>
      <visual name="rotor_2_visual">
        <pose>-0.022 -0.14638461538461536 -0.016 0 0 0</pose>
        <geometry>
          <mesh>
            <scale>0.8461538461538461 0.8461538461538461 0.8461538461538461</scale>
            <uri>model://x500/meshes/1345_prop_cw.stl</uri>
          </mesh>
        </geometry>
        <material>
          <script>
            <name>Gazebo/DarkGrey</name>
            <uri>file://media/materials/scripts/gazebo.material</uri>
          </script>
        </material>
      </visual>
      <collision name="rotor_2_collision">
        <pose>0 0 0 0 0 0 </pose>
        <geometry>
          <box>
            <size>0.2792307692307692 0.016923076923076923 0.0008461538461538462</size>
          </box>
        </geometry>
        <surface>
          <contact>
            <ode>
              <min_depth>0.001</min_depth>
              <max_vel>0</max_vel>
            </ode>
          </contact>
          <friction>
            <ode/>
          </friction>
        </surface>
      </collision>
    </link>
    <joint name="rotor_2_joint" type="revolute">
      <parent>base_link</parent>
      <child>rotor_2</child>
      <axis>
        <xyz>0 0 1</xyz>
        <limit>
          <lower>-1e+16</lower>
          <upper>1e+16</upper>
        </limit>
        <dynamics>
          <spring_reference>0</spring_reference>
          <spring_stiffness>0</spring_stiffness>
        </dynamics>
      </axis>
    </joint>
    <link name="rotor_3">
      <gravity>true</gravity>
      <self_collide>false</self_collide>
      <velocity_decay/>
      <pose>-0.174 -0.174 0.06 0 0 0</pose>
      <inertial>
          <mass>0.016076923076923075</mass>
          <inertia>
            <ixx>3.8464910483993325e-07</ixx>
            <iyy>2.6115851691700804e-05</iyy>
            <izz>2.649858234714004e-05</izz>
          </inertia>
        </inertial>
      <visual name="rotor_3_visual">
        <pose>-0.022 -0.14638461538461536 -0.016 0 0 0</pose>
        <geometry>
          <mesh>
            <scale>0.8461538461538461 0.8461538461538461 0.8461538461538461</scale>
            <uri>model://x500/meshes/1345_prop_cw.stl</uri>
          </mesh>
        </geometry>
        <material>
          <script>
            <name>Gazebo/DarkGrey</name>
            <uri>file://media/materials/scripts/gazebo.material</uri>
          </script>
        </material>
      </visual>
      <collision name="rotor_3_collision">
        <pose>0 0 0 0 0 0 </pose>
        <geometry>
          <box>
            <size>0.2792307692307692 0.016923076923076923 0.0008461538461538462</size>
          </box>
        </geometry>
        <surface>
          <contact>
            <ode>
              <min_depth>0.001</min_depth>
              <max_vel>0</max_vel>
            </ode>
          </contact>
          <friction>
            <ode/>
          </friction>
        </surface>
      </collision>
    </link>
    <joint name="rotor_3_joint" type="revolute">
      <parent>base_link</parent>
      <child>rotor_3</child>
      <axis>
        <xyz>0 0 1</xyz>
        <limit>
          <lower>-1e+16</lower>
          <upper>1e+16</upper>
        </limit>
        <dynamics>
          <spring_reference>0</spring_reference>
          <spring_stiffness>0</spring_stiffness>
        </dynamics>
      </axis>
    </joint>
   <plugin filename="gz-sim-multicopter-motor-model-system" name="gz::sim::systems::MulticopterMotorModel">
      <jointName>rotor_0_joint</jointName>
      <linkName>rotor_0</linkName>
      <turningDirection>ccw</turningDirection>
      <timeConstantUp>0.0125</timeConstantUp>
      <timeConstantDown>0.025</timeConstantDown>
      <maxRotVelocity>1000.0</maxRotVelocity>
      <motorConstant>8.54858e-06</motorConstant>
      <momentConstant>0.016</momentConstant>
      <commandSubTopic>command/motor_speed</commandSubTopic>
      <motorNumber>0</motorNumber>
      <rotorDragCoefficient>8.06428e-05</rotorDragCoefficient>
      <rollingMomentCoefficient>1e-06</rollingMomentCoefficient>
      <rotorVelocitySlowdownSim>10</rotorVelocitySlowdownSim>
      <motorType>velocity</motorType>
    </plugin>
    <plugin filename="gz-sim-multicopter-motor-model-system" name="gz::sim::systems::MulticopterMotorModel">
      <jointName>rotor_1_joint</jointName>
      <linkName>rotor_1</linkName>
      <turningDirection>ccw</turningDirection>
      <timeConstantUp>0.0125</timeConstantUp>
      <timeConstantDown>0.025</timeConstantDown>
      <maxRotVelocity>1000.0</maxRotVelocity>
      <motorConstant>8.54858e-06</motorConstant>
      <momentConstant>0.016</momentConstant>
      <commandSubTopic>command/motor_speed</commandSubTopic>
      <motorNumber>1</motorNumber>
      <rotorDragCoefficient>8.06428e-05</rotorDragCoefficient>
      <rollingMomentCoefficient>1e-06</rollingMomentCoefficient>
      <rotorVelocitySlowdownSim>10</rotorVelocitySlowdownSim>
      <motorType>velocity</motorType>
    </plugin>
    <plugin filename="gz-sim-multicopter-motor-model-system" name="gz::sim::systems::MulticopterMotorModel">
      <jointName>rotor_2_joint</jointName>
      <linkName>rotor_2</linkName>
      <turningDirection>cw</turningDirection>
      <timeConstantUp>0.0125</timeConstantUp>
      <timeConstantDown>0.025</timeConstantDown>
      <maxRotVelocity>1000.0</maxRotVelocity>
      <motorConstant>8.54858e-06</motorConstant>
      <momentConstant>0.016</momentConstant>
      <commandSubTopic>command/motor_speed</commandSubTopic>
      <motorNumber>2</motorNumber>
      <rotorDragCoefficient>8.06428e-05</rotorDragCoefficient>
      <rollingMomentCoefficient>1e-06</rollingMomentCoefficient>
      <rotorVelocitySlowdownSim>10</rotorVelocitySlowdownSim>
      <motorType>velocity</motorType>
    </plugin>
    <plugin filename="gz-sim-multicopter-motor-model-system" name="gz::sim::systems::MulticopterMotorModel">
      <jointName>rotor_3_joint</jointName>
      <linkName>rotor_3</linkName>
      <turningDirection>cw</turningDirection>
      <timeConstantUp>0.0125</timeConstantUp>
      <timeConstantDown>0.025</timeConstantDown>
      <maxRotVelocity>1000.0</maxRotVelocity>
      <motorConstant>8.54858e-06</motorConstant>
      <momentConstant>0.016</momentConstant>
      <commandSubTopic>command/motor_speed</commandSubTopic>
      <motorNumber>3</motorNumber>
      <rotorDragCoefficient>8.06428e-05</rotorDragCoefficient>
      <rollingMomentCoefficient>1e-06</rollingMomentCoefficient>
      <rotorVelocitySlowdownSim>10</rotorVelocitySlowdownSim>
      <motorType>velocity</motorType>
    </plugin>
  </model>
</sdf>
